<?xml version="1.0"?>
<robot name="panda_example">
  <link name="panda_link0">
    <visual>
      <geometry>
        <box size="0.18 0.18 0.08"/>
      </geometry>
    </visual>
    <inertial>
      <mass value="2.0"/>
      <inertia ixx="0.02" ixy="0" ixz="0" iyy="0.02" iyz="0" izz="0.02"/>
    </inertial>
  </link>

  <link name="panda_link1"/>
  <joint name="panda_joint1" type="revolute">
    <parent link="panda_link0"/>
    <child link="panda_link1"/>
    <origin xyz="0 0 0.333" rpy="0 0 0"/>
    <axis xyz="0 0 1"/>
    <limit lower="-2.8973" upper="2.8973" effort="87" velocity="2.175"/>
  </joint>

  <link name="panda_link2"/>
  <joint name="panda_joint2" type="revolute">
    <parent link="panda_link1"/>
    <child link="panda_link2"/>
    <origin xyz="0 0 0" rpy="-1.5708 0 0"/>
    <axis xyz="0 0 1"/>
    <limit lower="-1.7628" upper="1.7628" effort="87" velocity="2.175"/>
  </joint>

  <link name="panda_link3"/>
  <joint name="panda_joint3" type="revolute">
    <parent link="panda_link2"/>
    <child link="panda_link3"/>
    <origin xyz="0 -0.316 0" rpy="1.5708 0 0"/>
    <axis xyz="0 0 1"/>
    <limit lower="-2.8973" upper="2.8973" effort="87" velocity="2.175"/>
  </joint>

  <link name="panda_link4"/>
  <joint name="panda_joint4" type="revolute">
    <parent link="panda_link3"/>
    <child link="panda_link4"/>
    <origin xyz="0.0825 0 0" rpy="1.5708 0 0"/>
    <axis xyz="0 0 1"/>
    <limit lower="-3.0718" upper="-0.0698" effort="87" velocity="2.175"/>
  </joint>

  <link name="panda_link5"/>
  <joint name="panda_joint5" type="revolute">
    <parent link="panda_link4"/>
    <child link="panda_link5"/>
    <origin xyz="-0.0825 0.384 0" rpy="-1.5708 0 0"/>
    <axis xyz="0 0 1"/>
    <limit lower="-2.8973" upper="2.8973" effort="12" velocity="2.61"/>
  </joint>

  <link name="panda_link6"/>
  <joint name="panda_joint6" type="revolute">
    <parent link="panda_link5"/>
    <child link="panda_link6"/>
    <origin xyz="0 0 0" rpy="1.5708 0 0"/>
    <axis xyz="0 0 1"/>
    <limit lower="-0.0175" upper="3.7525" effort="12" velocity="2.61"/>
  </joint>

  <link name="panda_link7"/>
  <joint name="panda_joint7" type="revolute">
    <parent link="panda_link6"/>
    <child link="panda_link7"/>
    <origin xyz="0.088 0 0" rpy="1.5708 0 0"/>
    <axis xyz="0 0 1"/>
    <limit lower="-2.8973" upper="2.8973" effort="12" velocity="2.61"/>
  </joint>

  <link name="panda_hand">
    <visual>
      <geometry>
        <box size="0.10 0.08 0.08"/>
      </geometry>
    </visual>
  </link>
  <joint name="panda_hand_joint" type="fixed">
    <parent link="panda_link7"/>
    <child link="panda_hand"/>
    <origin xyz="0 0 0.107" rpy="0 0 0"/>
  </joint>

  <link name="panda_leftfinger"/>
  <link name="panda_rightfinger"/>
  <joint name="panda_finger_joint1" type="prismatic">
    <parent link="panda_hand"/>
    <child link="panda_leftfinger"/>
    <origin xyz="0 0.04 0.058" rpy="0 0 0"/>
    <axis xyz="0 1 0"/>
    <limit lower="0" upper="0.04" effort="20" velocity="0.2"/>
  </joint>
  <joint name="panda_finger_joint2" type="prismatic">
    <parent link="panda_hand"/>
    <child link="panda_rightfinger"/>
    <origin xyz="0 -0.04 0.058" rpy="0 0 0"/>
    <axis xyz="0 -1 0"/>
    <limit lower="0" upper="0.04" effort="20" velocity="0.2"/>
  </joint>

  <transmission name="panda_joint_trajectory_transmission">
    <type>transmission_interface/SimpleTransmission</type>
    <joint name="panda_joint1"/>
    <actuator name="panda_joint_motor"/>
  </transmission>
</robot>
